Workbook
Name BuilderList: Builders!$A$2:$A$201
Name TitleList: 'Title Companies'!$A$2:$A$101
Name RoleList: Lists!$A$2:$A$31
Name TitleRoleList: Lists!$B$2:$B$7

Sheet START HERE
B2: TRL CONTACTS
B3: How this workbook works - read this once and you'll never be lost.
B5: THE TABS
B6: Dashboard (blue) | C6: The page everyone uses day to day. Pick a builder in the yellow box and every contact, the concession rules, the Dropbox folder and the escrow team fill in automatically. Emails and the Dropbox link are clickable there.
B7: Builders (green) | C7: ONE ROW PER BUILDER. Title company, Dropbox link, concession rules, special process, and communication rules (who to CC).
B8: Contacts (green) | C8: ONE ROW PER PERSON. Pick the builder and their main Role from the dropdowns, then use the 'What They Handle' column to say exactly when to contact them. Columns K and L are hidden helpers - leave them alone.
B9: Title Companies (green) | C9: ONE ROW PER TITLE COMPANY. Team email, office phone and address. Builders link here by the exact company name. The people are on the next tab.
B10: Title Contacts (green) | C10: ONE ROW PER PERSON AT A TITLE COMPANY, up to 6 per company - escrow agent, assistant, closer, whoever else. Pick the company and the role from the dropdowns.
B11: General Contacts (green) | C11: ONE ROW PER PERSON who is not tied to one builder - two phone numbers, two emails and notes. Nothing else on the workbook reads this tab.
B12: To Fill In (orange) | C12: Automatic gap report. Anything red says MISSING - go fill it in on the green tabs. The '# Missing' column shows how much is left per builder.
B13: Lists (grey) | C13: Feeds the Role dropdowns. Add a value there to make it selectable.
B15: THE ONE RULE | C15: Builder names and title company names must be spelled EXACTLY the same everywhere they appear - that text is what links the tabs together. Always pick from the dropdowns instead of typing. If a name does not match, the row lights up RED on the green tabs.
B17: ADDING A NEW BUILDER | C17: 1) Add the row on Builders. 2) Add their people on Contacts (one row per person). 3) If their title company is new, add it on Title Companies first and its people on Title Contacts, then pick the company in the Builders row. 4) Check To Fill In for what's still missing.
B18: UPDATING A PERSON | C18: Find their one row on Contacts (or Title Contacts) and fix it there - phone, email, role, whatever changed. It updates the Dashboard automatically.
B20: NEW TEAM MEMBER? WORKING A FILE? | C20: 1) Open the Dashboard and pick the builder. 2) Read Concessions, Special Process and Communication Rules BEFORE structuring or emailing - most builder-specific mistakes live there. 3) The contact list says exactly who handles builder docs, appraisals, and seller-signed items.
... B25: IF SOMETHING LOOKS WRONG | C25: A contact or escrow team not showing on the Dashboard is almost always a spelling mismatch in a builder or title company name. Re-pick the name from the dropdown and it will snap back.
B28: MAINTENANCE - FOR WHOEVER OWNS THIS FILE NEXT
B29: No code, ever | C29: There are no macros, no scripts, no add-ins. Everything is plain Excel formulas. If Excel ever asks to enable macros, something is wrong - do not.
B30: No passwords | C30: Protected tabs (Dashboard, To Fill In, Start Here) have NO password. Review > Unprotect Sheet unlocks them instantly. Re-protect when you're done.
B31: Capacity | C31: Built for 200 builders, 500 contacts, 100 title companies (6 people each) and 500 general contacts. The formulas stop at those rows - past that, extend (below) or start a second file.
B32: Adding a role | C32: Type it on the Lists tab under the last role. Column A feeds the Contacts role dropdown (30 slots), column B feeds the Title Contacts one. If every slot is used, extend the list: Formulas > Name Manager > RoleList > change $A$31 to the new last row.
B33: Extending capacity | C33: 1) Formulas > Name Manager: extend BuilderList / TitleList to the new last row. 2) On Contacts: unhide columns K:L, copy the last row's K and L cells down, re-hide. 3) On Title Contacts: unhide column G and do the same. 4) On To Fill In: unprotect, copy the last row across B:M down as far as needed, re-protect. If that sounds scary, it is easier to start a second file.
B34: Hidden helper columns | C34: Contacts column K builds a key ('Cullers Homes|1', '|2', ...) that the Dashboard uses to list a builder's contacts in order; column L combines the assistant's name / phone / email. Title Contacts column G does the same job for the escrow team. If they ever break, paste these into K2 and L2, then fill down to row 501:
C35: K2: =IF($A2="","",$A2&"|"&COUNTIF($A$2:$A2,$A2))
C36: L2: =IF($G2="","",$G2&IF($H2="",""," / "&$H2)&IF($I2="",""," / "&$I2))
B37: Backups | C37: The file lives in Dropbox. dropbox.com > the file > Version history restores any earlier version if something breaks.
B38: How this file was made | C38: Exported from the TRL Contacts web app. The web app is the live database - this file is a point-in-time snapshot of it, fully self-contained, standard Excel.

Sheet Dashboard
A1: BUILDER PROFILE DASHBOARD
A2: Pick a builder in the yellow box. Everything below fills in automatically - to change anything, edit the green tabs, never type here. Emails and the Dropbox link are clickable. | H2: =IFERROR(MATCH($B$4,Builders!$A$2:$A$201,0),"")
H3: =IF($H$2="","",IFERROR(MATCH(INDEX(Builders!$B$2:$B$201,$H$2),'Title Companies'!$A$2:$A$101,0),""))
A4: SELECT BUILDER: | D4: < click the yellow box for the dropdown | H4: =IF($H$2="","",INDEX(Builders!$B$2:$B$201,$H$2)&"")
A5: =IF($H$2="","Pick a builder in the yellow box above.",IF($H$5="","Nothing missing - this builder's info is complete.","STILL MISSING: "&LEFT($H$5,LEN($H$5)-2)&" (fill in on the green tabs)")) | H5: =IF($H$2="","",IF(INDEX('To Fill In'!$B$5:$B$204,$H$2)="MISSING","Title Company, ","")&IF(INDEX('To Fill In'!$C$5:$C$204,$H$2)="MISSING","Dropbox, ","")&IF(INDEX('To Fill In'!$D$5:$D$204,$H$2)="MISSING","Concession Terms, ","")&IF(INDEX('To Fill In'!$E$5:$E$204,$H$2)="MISSING","Allowed Uses, ","")&IF(INDEX('To Fill In'!$F$5:$F$204,$H$2)="MISSING","Owner, ","")&IF(INDEX('To Fill In'!$G$5:$G$204,$H$2)="MISSING","Listing Agent, ","")&IF(INDEX('To Fill In'!$H$5:$H$204,$H$2)="MISSING","Builder Rep, ","")&IF(INDEX('To Fill In'!$I$5:$I$204,$H$2)="MISSING","Builder Docs POC, ","")&IF(INDEX('To Fill In'!$J$5:$J$204,$H$2)="MISSING","Appraisal POC, ","")&IF(INDEX('To Fill In'!$K$5:$K$204,$H$2)="MISSING","Escrow Agent, ","")&IF(INDEX('To Fill In'!$L$5:$L$204,$H$2)="MISSING","Escrow Assistant, ",""))
A7: BUILDER OVERVIEW
A8: Title Company | B8: =IF($H$2="","-",IF(INDEX(Builders!$B$2:$B$201,$H$2)="","-",INDEX(Builders!$B$2:$B$201,$H$2)))
A9: Dropbox Folder | B9: =IF($H$2="","-",IF(INDEX(Builders!$C$2:$C$201,$H$2)="","-",IF(LEFT(INDEX(Builders!$C$2:$C$201,$H$2),4)="http",HYPERLINK(INDEX(Builders!$C$2:$C$201,$H$2),"Open Dropbox folder >>"),INDEX(Builders!$C$2:$C$201,$H$2))))
A10: Concession Amount / % | B10: =IF($H$2="","-",IF(INDEX(Builders!$D$2:$D$201,$H$2)="","-",INDEX(Builders!$D$2:$D$201,$H$2)))
A11: Calculated From | B11: =IF($H$2="","-",IF(INDEX(Builders!$E$2:$E$201,$H$2)="","-",INDEX(Builders!$E$2:$E$201,$H$2)))
A12: Allowed Uses & Details | B12: =IF($H$2="","-",IF(INDEX(Builders!$F$2:$F$201,$H$2)="","-",INDEX(Builders!$F$2:$F$201,$H$2)))
A13: Special Process & Incentives | B13: =IF($H$2="","-",IF(INDEX(Builders!$G$2:$G$201,$H$2)="","-",INDEX(Builders!$G$2:$G$201,$H$2)))
A14: Communication Rules | B14: =IF($H$2="","-",IF(INDEX(Builders!$H$2:$H$201,$H$2)="","-",INDEX(Builders!$H$2:$H$201,$H$2)))
A15: General Notes | B15: =IF($H$2="","-",IF(INDEX(Builders!$I$2:$I$201,$H$2)="","-",INDEX(Builders!$I$2:$I$201,$H$2)))
A17: ALL CONTACTS FOR THIS BUILDER
A18: Role | B18: Name | C18: Phone | D18: Email | E18: What They Handle / When to Contact | F18: Assistant (name / phone / email)
A19: =IF(COUNTIF(Contacts!$K$2:$K$501,$B$4&"|"&1)=0,"",INDEX(Contacts!$B$2:$B$501,MATCH($B$4&"|"&1,Contacts!$K$2:$K$501,0))&"") | B19: =IF(COUNTIF(Contacts!$K$2:$K$501,$B$4&"|"&1)=0,"",INDEX(Contacts!$C$2:$C$501,MATCH($B$4&"|"&1,Contacts!$K$2:$K$501,0))&"") | C19: =IF(COUNTIF(Contacts!$K$2:$K$501,$B$4&"|"&1)=0,"",INDEX(Contacts!$D$2:$D$501,MATCH($B$4&"|"&1,Contacts!$K$2:$K$501,0))&"") | D19: =IF($H19="","",IF(ISNUMBER(SEARCH("@",$H19)),HYPERLINK("mailto:"&$H19,$H19),$H19)) | E19: =IF(COUNTIF(Contacts!$K$2:$K$501,$B$4&"|"&1)=0,"",INDEX(Contacts!$F$2:$F$501,MATCH($B$4&"|"&1,Contacts!$K$2:$K$501,0))&"") | F19: =IF(COUNTIF(Contacts!$K$2:$K$501,$B$4&"|"&1)=0,"",INDEX(Contacts!$L$2:$L$501,MATCH($B$4&"|"&1,Contacts!$K$2:$K$501,0))&"") | H19: =IF(COUNTIF(Contacts!$K$2:$K$501,$B$4&"|"&1)=0,"",INDEX(Contacts!$E$2:$E$501,MATCH($B$4&"|"&1,Contacts!$K$2:$K$501,0))&"")
A20: =IF(COUNTIF(Contacts!$K$2:$K$501,$B$4&"|"&2)=0,"",INDEX(Contacts!$B$2:$B$501,MATCH($B$4&"|"&2,Contacts!$K$2:$K$501,0))&"") | B20: =IF(COUNTIF(Contacts!$K$2:$K$501,$B$4&"|"&2)=0,"",INDEX(Contacts!$C$2:$C$501,MATCH($B$4&"|"&2,Contacts!$K$2:$K$501,0))&"") | C20: =IF(COUNTIF(Contacts!$K$2:$K$501,$B$4&"|"&2)=0,"",INDEX(Contacts!$D$2:$D$501,MATCH($B$4&"|"&2,Contacts!$K$2:$K$501,0))&"") | D20: =IF($H20="","",IF(ISNUMBER(SEARCH("@",$H20)),HYPERLINK("mailto:"&$H20,$H20),$H20)) | E20: =IF(COUNTIF(Contacts!$K$2:$K$501,$B$4&"|"&2)=0,"",INDEX(Contacts!$F$2:$F$501,MATCH($B$4&"|"&2,Contacts!$K$2:$K$501,0))&"") | F20: =IF(COUNTIF(Contacts!$K$2:$K$501,$B$4&"|"&2)=0,"",INDEX(Contacts!$L$2:$L$501,MATCH($B$4&"|"&2,Contacts!$K$2:$K$501,0))&"") | H20: =IF(COUNTIF(Contacts!$K$2:$K$501,$B$4&"|"&2)=0,"",INDEX(Contacts!$E$2:$E$501,MATCH($B$4&"|"&2,Contacts!$K$2:$K$501,0))&"")
A21: =IF(COUNTIF(Contacts!$K$2:$K$501,$B$4&"|"&3)=0,"",INDEX(Contacts!$B$2:$B$501,MATCH($B$4&"|"&3,Contacts!$K$2:$K$501,0))&"") | B21: =IF(COUNTIF(Contacts!$K$2:$K$501,$B$4&"|"&3)=0,"",INDEX(Contacts!$C$2:$C$501,MATCH($B$4&"|"&3,Contacts!$K$2:$K$501,0))&"") | C21: =IF(COUNTIF(Contacts!$K$2:$K$501,$B$4&"|"&3)=0,"",INDEX(Contacts!$D$2:$D$501,MATCH($B$4&"|"&3,Contacts!$K$2:$K$501,0))&"") | D21: =IF($H21="","",IF(ISNUMBER(SEARCH("@",$H21)),HYPERLINK("mailto:"&$H21,$H21),$H21)) | E21: =IF(COUNTIF(Contacts!$K$2:$K$501,$B$4&"|"&3)=0,"",INDEX(Contacts!$F$2:$F$501,MATCH($B$4&"|"&3,Contacts!$K$2:$K$501,0))&"") | F21: =IF(COUNTIF(Contacts!$K$2:$K$501,$B$4&"|"&3)=0,"",INDEX(Contacts!$L$2:$L$501,MATCH($B$4&"|"&3,Contacts!$K$2:$K$501,0))&"") | H21: =IF(COUNTIF(Contacts!$K$2:$K$501,$B$4&"|"&3)=0,"",INDEX(Contacts!$E$2:$E$501,MATCH($B$4&"|"&3,Contacts!$K$2:$K$501,0))&"")
A22: =IF(COUNTIF(Contacts!$K$2:$K$501,$B$4&"|"&4)=0,"",INDEX(Contacts!$B$2:$B$501,MATCH($B$4&"|"&4,Contacts!$K$2:$K$501,0))&"") | B22: =IF(COUNTIF(Contacts!$K$2:$K$501,$B$4&"|"&4)=0,"",INDEX(Contacts!$C$2:$C$501,MATCH($B$4&"|"&4,Contacts!$K$2:$K$501,0))&"") | C22: =IF(COUNTIF(Contacts!$K$2:$K$501,$B$4&"|"&4)=0,"",INDEX(Contacts!$D$2:$D$501,MATCH($B$4&"|"&4,Contacts!$K$2:$K$501,0))&"") | D22: =IF($H22="","",IF(ISNUMBER(SEARCH("@",$H22)),HYPERLINK("mailto:"&$H22,$H22),$H22)) | E22: =IF(COUNTIF(Contacts!$K$2:$K$501,$B$4&"|"&4)=0,"",INDEX(Contacts!$F$2:$F$501,MATCH($B$4&"|"&4,Contacts!$K$2:$K$501,0))&"") | F22: =IF(COUNTIF(Contacts!$K$2:$K$501,$B$4&"|"&4)=0,"",INDEX(Contacts!$L$2:$L$501,MATCH($B$4&"|"&4,Contacts!$K$2:$K$501,0))&"") | H22: =IF(COUNTIF(Contacts!$K$2:$K$501,$B$4&"|"&4)=0,"",INDEX(Contacts!$E$2:$E$501,MATCH($B$4&"|"&4,Contacts!$K$2:$K$501,0))&"")
A23: =IF(COUNTIF(Contacts!$K$2:$K$501,$B$4&"|"&5)=0,"",INDEX(Contacts!$B$2:$B$501,MATCH($B$4&"|"&5,Contacts!$K$2:$K$501,0))&"") | B23: =IF(COUNTIF(Contacts!$K$2:$K$501,$B$4&"|"&5)=0,"",INDEX(Contacts!$C$2:$C$501,MATCH($B$4&"|"&5,Contacts!$K$2:$K$501,0))&"") | C23: =IF(COUNTIF(Contacts!$K$2:$K$501,$B$4&"|"&5)=0,"",INDEX(Contacts!$D$2:$D$501,MATCH($B$4&"|"&5,Contacts!$K$2:$K$501,0))&"") | D23: =IF($H23="","",IF(ISNUMBER(SEARCH("@",$H23)),HYPERLINK("mailto:"&$H23,$H23),$H23)) | E23: =IF(COUNTIF(Contacts!$K$2:$K$501,$B$4&"|"&5)=0,"",INDEX(Contacts!$F$2:$F$501,MATCH($B$4&"|"&5,Contacts!$K$2:$K$501,0))&"") | F23: =IF(COUNTIF(Contacts!$K$2:$K$501,$B$4&"|"&5)=0,"",INDEX(Contacts!$L$2:$L$501,MATCH($B$4&"|"&5,Contacts!$K$2:$K$501,0))&"") | H23: =IF(COUNTIF(Contacts!$K$2:$K$501,$B$4&"|"&5)=0,"",INDEX(Contacts!$E$2:$E$501,MATCH($B$4&"|"&5,Contacts!$K$2:$K$501,0))&"")
A24: =IF(COUNTIF(Contacts!$K$2:$K$501,$B$4&"|"&6)=0,"",INDEX(Contacts!$B$2:$B$501,MATCH($B$4&"|"&6,Contacts!$K$2:$K$501,0))&"") | B24: =IF(COUNTIF(Contacts!$K$2:$K$501,$B$4&"|"&6)=0,"",INDEX(Contacts!$C$2:$C$501,MATCH($B$4&"|"&6,Contacts!$K$2:$K$501,0))&"") | C24: =IF(COUNTIF(Contacts!$K$2:$K$501,$B$4&"|"&6)=0,"",INDEX(Contacts!$D$2:$D$501,MATCH($B$4&"|"&6,Contacts!$K$2:$K$501,0))&"") | D24: =IF($H24="","",IF(ISNUMBER(SEARCH("@",$H24)),HYPERLINK("mailto:"&$H24,$H24),$H24)) | E24: =IF(COUNTIF(Contacts!$K$2:$K$501,$B$4&"|"&6)=0,"",INDEX(Contacts!$F$2:$F$501,MATCH($B$4&"|"&6,Contacts!$K$2:$K$501,0))&"") | F24: =IF(COUNTIF(Contacts!$K$2:$K$501,$B$4&"|"&6)=0,"",INDEX(Contacts!$L$2:$L$501,MATCH($B$4&"|"&6,Contacts!$K$2:$K$501,0))&"") | H24: =IF(COUNTIF(Contacts!$K$2:$K$501,$B$4&"|"&6)=0,"",INDEX(Contacts!$E$2:$E$501,MATCH($B$4&"|"&6,Contacts!$K$2:$K$501,0))&"")
A25: =IF(COUNTIF(Contacts!$K$2:$K$501,$B$4&"|"&7)=0,"",INDEX(Contacts!$B$2:$B$501,MATCH($B$4&"|"&7,Contacts!$K$2:$K$501,0))&"") | B25: =IF(COUNTIF(Contacts!$K$2:$K$501,$B$4&"|"&7)=0,"",INDEX(Contacts!$C$2:$C$501,MATCH($B$4&"|"&7,Contacts!$K$2:$K$501,0))&"") | C25: =IF(COUNTIF(Contacts!$K$2:$K$501,$B$4&"|"&7)=0,"",INDEX(Contacts!$D$2:$D$501,MATCH($B$4&"|"&7,Contacts!$K$2:$K$501,0))&"") | D25: =IF($H25="","",IF(ISNUMBER(SEARCH("@",$H25)),HYPERLINK("mailto:"&$H25,$H25),$H25)) | E25: =IF(COUNTIF(Contacts!$K$2:$K$501,$B$4&"|"&7)=0,"",INDEX(Contacts!$F$2:$F$501,MATCH($B$4&"|"&7,Contacts!$K$2:$K$501,0))&"") | F25: =IF(COUNTIF(Contacts!$K$2:$K$501,$B$4&"|"&7)=0,"",INDEX(Contacts!$L$2:$L$501,MATCH($B$4&"|"&7,Contacts!$K$2:$K$501,0))&"") | H25: =IF(COUNTIF(Contacts!$K$2:$K$501,$B$4&"|"&7)=0,"",INDEX(Contacts!$E$2:$E$501,MATCH($B$4&"|"&7,Contacts!$K$2:$K$501,0))&"")
A26: =IF(COUNTIF(Contacts!$K$2:$K$501,$B$4&"|"&8)=0,"",INDEX(Contacts!$B$2:$B$501,MATCH($B$4&"|"&8,Contacts!$K$2:$K$501,0))&"") | B26: =IF(COUNTIF(Contacts!$K$2:$K$501,$B$4&"|"&8)=0,"",INDEX(Contacts!$C$2:$C$501,MATCH($B$4&"|"&8,Contacts!$K$2:$K$501,0))&"") | C26: =IF(COUNTIF(Contacts!$K$2:$K$501,$B$4&"|"&8)=0,"",INDEX(Contacts!$D$2:$D$501,MATCH($B$4&"|"&8,Contacts!$K$2:$K$501,0))&"") | D26: =IF($H26="","",IF(ISNUMBER(SEARCH("@",$H26)),HYPERLINK("mailto:"&$H26,$H26),$H26)) | E26: =IF(COUNTIF(Contacts!$K$2:$K$501,$B$4&"|"&8)=0,"",INDEX(Contacts!$F$2:$F$501,MATCH($B$4&"|"&8,Contacts!$K$2:$K$501,0))&"") | F26: =IF(COUNTIF(Contacts!$K$2:$K$501,$B$4&"|"&8)=0,"",INDEX(Contacts!$L$2:$L$501,MATCH($B$4&"|"&8,Contacts!$K$2:$K$501,0))&"") | H26: =IF(COUNTIF(Contacts!$K$2:$K$501,$B$4&"|"&8)=0,"",INDEX(Contacts!$E$2:$E$501,MATCH($B$4&"|"&8,Contacts!$K$2:$K$501,0))&"")
A27: =IF(COUNTIF(Contacts!$K$2:$K$501,$B$4&"|"&9)=0,"",INDEX(Contacts!$B$2:$B$501,MATCH($B$4&"|"&9,Contacts!$K$2:$K$501,0))&"") | B27: =IF(COUNTIF(Contacts!$K$2:$K$501,$B$4&"|"&9)=0,"",INDEX(Contacts!$C$2:$C$501,MATCH($B$4&"|"&9,Contacts!$K$2:$K$501,0))&"") | C27: =IF(COUNTIF(Contacts!$K$2:$K$501,$B$4&"|"&9)=0,"",INDEX(Contacts!$D$2:$D$501,MATCH($B$4&"|"&9,Contacts!$K$2:$K$501,0))&"") | D27: =IF($H27="","",IF(ISNUMBER(SEARCH("@",$H27)),HYPERLINK("mailto:"&$H27,$H27),$H27)) | E27: =IF(COUNTIF(Contacts!$K$2:$K$501,$B$4&"|"&9)=0,"",INDEX(Contacts!$F$2:$F$501,MATCH($B$4&"|"&9,Contacts!$K$2:$K$501,0))&"") | F27: =IF(COUNTIF(Contacts!$K$2:$K$501,$B$4&"|"&9)=0,"",INDEX(Contacts!$L$2:$L$501,MATCH($B$4&"|"&9,Contacts!$K$2:$K$501,0))&"") | H27: =IF(COUNTIF(Contacts!$K$2:$K$501,$B$4&"|"&9)=0,"",INDEX(Contacts!$E$2:$E$501,MATCH($B$4&"|"&9,Contacts!$K$2:$K$501,0))&"")
A28: =IF(COUNTIF(Contacts!$K$2:$K$501,$B$4&"|"&10)=0,"",INDEX(Contacts!$B$2:$B$501,MATCH($B$4&"|"&10,Contacts!$K$2:$K$501,0))&"") | B28: =IF(COUNTIF(Contacts!$K$2:$K$501,$B$4&"|"&10)=0,"",INDEX(Contacts!$C$2:$C$501,MATCH($B$4&"|"&10,Contacts!$K$2:$K$501,0))&"") | C28: =IF(COUNTIF(Contacts!$K$2:$K$501,$B$4&"|"&10)=0,"",INDEX(Contacts!$D$2:$D$501,MATCH($B$4&"|"&10,Contacts!$K$2:$K$501,0))&"") | D28: =IF($H28="","",IF(ISNUMBER(SEARCH("@",$H28)),HYPERLINK("mailto:"&$H28,$H28),$H28)) | E28: =IF(COUNTIF(Contacts!$K$2:$K$501,$B$4&"|"&10)=0,"",INDEX(Contacts!$F$2:$F$501,MATCH($B$4&"|"&10,Contacts!$K$2:$K$501,0))&"") | F28: =IF(COUNTIF(Contacts!$K$2:$K$501,$B$4&"|"&10)=0,"",INDEX(Contacts!$L$2:$L$501,MATCH($B$4&"|"&10,Contacts!$K$2:$K$501,0))&"") | H28: =IF(COUNTIF(Contacts!$K$2:$K$501,$B$4&"|"&10)=0,"",INDEX(Contacts!$E$2:$E$501,MATCH($B$4&"|"&10,Contacts!$K$2:$K$501,0))&"")
A29: =IF(COUNTIF(Contacts!$K$2:$K$501,$B$4&"|"&11)=0,"",INDEX(Contacts!$B$2:$B$501,MATCH($B$4&"|"&11,Contacts!$K$2:$K$501,0))&"") | B29: =IF(COUNTIF(Contacts!$K$2:$K$501,$B$4&"|"&11)=0,"",INDEX(Contacts!$C$2:$C$501,MATCH($B$4&"|"&11,Contacts!$K$2:$K$501,0))&"") | C29: =IF(COUNTIF(Contacts!$K$2:$K$501,$B$4&"|"&11)=0,"",INDEX(Contacts!$D$2:$D$501,MATCH($B$4&"|"&11,Contacts!$K$2:$K$501,0))&"") | D29: =IF($H29="","",IF(ISNUMBER(SEARCH("@",$H29)),HYPERLINK("mailto:"&$H29,$H29),$H29)) | E29: =IF(COUNTIF(Contacts!$K$2:$K$501,$B$4&"|"&11)=0,"",INDEX(Contacts!$F$2:$F$501,MATCH($B$4&"|"&11,Contacts!$K$2:$K$501,0))&"") | F29: =IF(COUNTIF(Contacts!$K$2:$K$501,$B$4&"|"&11)=0,"",INDEX(Contacts!$L$2:$L$501,MATCH($B$4&"|"&11,Contacts!$K$2:$K$501,0))&"") | H29: =IF(COUNTIF(Contacts!$K$2:$K$501,$B$4&"|"&11)=0,"",INDEX(Contacts!$E$2:$E$501,MATCH($B$4&"|"&11,Contacts!$K$2:$K$501,0))&"")
A30: =IF(COUNTIF(Contacts!$K$2:$K$501,$B$4&"|"&12)=0,"",INDEX(Contacts!$B$2:$B$501,MATCH($B$4&"|"&12,Contacts!$K$2:$K$501,0))&"") | B30: =IF(COUNTIF(Contacts!$K$2:$K$501,$B$4&"|"&12)=0,"",INDEX(Contacts!$C$2:$C$501,MATCH($B$4&"|"&12,Contacts!$K$2:$K$501,0))&"") | C30: =IF(COUNTIF(Contacts!$K$2:$K$501,$B$4&"|"&12)=0,"",INDEX(Contacts!$D$2:$D$501,MATCH($B$4&"|"&12,Contacts!$K$2:$K$501,0))&"") | D30: =IF($H30="","",IF(ISNUMBER(SEARCH("@",$H30)),HYPERLINK("mailto:"&$H30,$H30),$H30)) | E30: =IF(COUNTIF(Contacts!$K$2:$K$501,$B$4&"|"&12)=0,"",INDEX(Contacts!$F$2:$F$501,MATCH($B$4&"|"&12,Contacts!$K$2:$K$501,0))&"") | F30: =IF(COUNTIF(Contacts!$K$2:$K$501,$B$4&"|"&12)=0,"",INDEX(Contacts!$L$2:$L$501,MATCH($B$4&"|"&12,Contacts!$K$2:$K$501,0))&"") | H30: =IF(COUNTIF(Contacts!$K$2:$K$501,$B$4&"|"&12)=0,"",INDEX(Contacts!$E$2:$E$501,MATCH($B$4&"|"&12,Contacts!$K$2:$K$501,0))&"")
A31: =IF(COUNTIF(Contacts!$K$2:$K$501,$B$4&"|"&13)=0,"",INDEX(Contacts!$B$2:$B$501,MATCH($B$4&"|"&13,Contacts!$K$2:$K$501,0))&"") | B31: =IF(COUNTIF(Contacts!$K$2:$K$501,$B$4&"|"&13)=0,"",INDEX(Contacts!$C$2:$C$501,MATCH($B$4&"|"&13,Contacts!$K$2:$K$501,0))&"") | C31: =IF(COUNTIF(Contacts!$K$2:$K$501,$B$4&"|"&13)=0,"",INDEX(Contacts!$D$2:$D$501,MATCH($B$4&"|"&13,Contacts!$K$2:$K$501,0))&"") | D31: =IF($H31="","",IF(ISNUMBER(SEARCH("@",$H31)),HYPERLINK("mailto:"&$H31,$H31),$H31)) | E31: =IF(COUNTIF(Contacts!$K$2:$K$501,$B$4&"|"&13)=0,"",INDEX(Contacts!$F$2:$F$501,MATCH($B$4&"|"&13,Contacts!$K$2:$K$501,0))&"") | F31: =IF(COUNTIF(Contacts!$K$2:$K$501,$B$4&"|"&13)=0,"",INDEX(Contacts!$L$2:$L$501,MATCH($B$4&"|"&13,Contacts!$K$2:$K$501,0))&"") | H31: =IF(COUNTIF(Contacts!$K$2:$K$501,$B$4&"|"&13)=0,"",INDEX(Contacts!$E$2:$E$501,MATCH($B$4&"|"&13,Contacts!$K$2:$K$501,0))&"")
A32: =IF(COUNTIF(Contacts!$K$2:$K$501,$B$4&"|"&14)=0,"",INDEX(Contacts!$B$2:$B$501,MATCH($B$4&"|"&14,Contacts!$K$2:$K$501,0))&"") | B32: =IF(COUNTIF(Contacts!$K$2:$K$501,$B$4&"|"&14)=0,"",INDEX(Contacts!$C$2:$C$501,MATCH($B$4&"|"&14,Contacts!$K$2:$K$501,0))&"") | C32: =IF(COUNTIF(Contacts!$K$2:$K$501,$B$4&"|"&14)=0,"",INDEX(Contacts!$D$2:$D$501,MATCH($B$4&"|"&14,Contacts!$K$2:$K$501,0))&"") | D32: =IF($H32="","",IF(ISNUMBER(SEARCH("@",$H32)),HYPERLINK("mailto:"&$H32,$H32),$H32)) | E32: =IF(COUNTIF(Contacts!$K$2:$K$501,$B$4&"|"&14)=0,"",INDEX(Contacts!$F$2:$F$501,MATCH($B$4&"|"&14,Contacts!$K$2:$K$501,0))&"") | F32: =IF(COUNTIF(Contacts!$K$2:$K$501,$B$4&"|"&14)=0,"",INDEX(Contacts!$L$2:$L$501,MATCH($B$4&"|"&14,Contacts!$K$2:$K$501,0))&"") | H32: =IF(COUNTIF(Contacts!$K$2:$K$501,$B$4&"|"&14)=0,"",INDEX(Contacts!$E$2:$E$501,MATCH($B$4&"|"&14,Contacts!$K$2:$K$501,0))&"")
A33: =IF(COUNTIF(Contacts!$K$2:$K$501,$B$4&"|"&15)=0,"",INDEX(Contacts!$B$2:$B$501,MATCH($B$4&"|"&15,Contacts!$K$2:$K$501,0))&"") | B33: =IF(COUNTIF(Contacts!$K$2:$K$501,$B$4&"|"&15)=0,"",INDEX(Contacts!$C$2:$C$501,MATCH($B$4&"|"&15,Contacts!$K$2:$K$501,0))&"") | C33: =IF(COUNTIF(Contacts!$K$2:$K$501,$B$4&"|"&15)=0,"",INDEX(Contacts!$D$2:$D$501,MATCH($B$4&"|"&15,Contacts!$K$2:$K$501,0))&"") | D33: =IF($H33="","",IF(ISNUMBER(SEARCH("@",$H33)),HYPERLINK("mailto:"&$H33,$H33),$H33)) | E33: =IF(COUNTIF(Contacts!$K$2:$K$501,$B$4&"|"&15)=0,"",INDEX(Contacts!$F$2:$F$501,MATCH($B$4&"|"&15,Contacts!$K$2:$K$501,0))&"") | F33: =IF(COUNTIF(Contacts!$K$2:$K$501,$B$4&"|"&15)=0,"",INDEX(Contacts!$L$2:$L$501,MATCH($B$4&"|"&15,Contacts!$K$2:$K$501,0))&"") | H33: =IF(COUNTIF(Contacts!$K$2:$K$501,$B$4&"|"&15)=0,"",INDEX(Contacts!$E$2:$E$501,MATCH($B$4&"|"&15,Contacts!$K$2:$K$501,0))&"")
A34: =IF(COUNTIF(Contacts!$K$2:$K$501,$B$4&"|"&16)=0,"",INDEX(Contacts!$B$2:$B$501,MATCH($B$4&"|"&16,Contacts!$K$2:$K$501,0))&"") | B34: =IF(COUNTIF(Contacts!$K$2:$K$501,$B$4&"|"&16)=0,"",INDEX(Contacts!$C$2:$C$501,MATCH($B$4&"|"&16,Contacts!$K$2:$K$501,0))&"") | C34: =IF(COUNTIF(Contacts!$K$2:$K$501,$B$4&"|"&16)=0,"",INDEX(Contacts!$D$2:$D$501,MATCH($B$4&"|"&16,Contacts!$K$2:$K$501,0))&"") | D34: =IF($H34="","",IF(ISNUMBER(SEARCH("@",$H34)),HYPERLINK("mailto:"&$H34,$H34),$H34)) | E34: =IF(COUNTIF(Contacts!$K$2:$K$501,$B$4&"|"&16)=0,"",INDEX(Contacts!$F$2:$F$501,MATCH($B$4&"|"&16,Contacts!$K$2:$K$501,0))&"") | F34: =IF(COUNTIF(Contacts!$K$2:$K$501,$B$4&"|"&16)=0,"",INDEX(Contacts!$L$2:$L$501,MATCH($B$4&"|"&16,Contacts!$K$2:$K$501,0))&"") | H34: =IF(COUNTIF(Contacts!$K$2:$K$501,$B$4&"|"&16)=0,"",INDEX(Contacts!$E$2:$E$501,MATCH($B$4&"|"&16,Contacts!$K$2:$K$501,0))&"")
A35: =IF(COUNTIF(Contacts!$K$2:$K$501,$B$4&"|"&17)=0,"",INDEX(Contacts!$B$2:$B$501,MATCH($B$4&"|"&17,Contacts!$K$2:$K$501,0))&"") | B35: =IF(COUNTIF(Contacts!$K$2:$K$501,$B$4&"|"&17)=0,"",INDEX(Contacts!$C$2:$C$501,MATCH($B$4&"|"&17,Contacts!$K$2:$K$501,0))&"") | C35: =IF(COUNTIF(Contacts!$K$2:$K$501,$B$4&"|"&17)=0,"",INDEX(Contacts!$D$2:$D$501,MATCH($B$4&"|"&17,Contacts!$K$2:$K$501,0))&"") | D35: =IF($H35="","",IF(ISNUMBER(SEARCH("@",$H35)),HYPERLINK("mailto:"&$H35,$H35),$H35)) | E35: =IF(COUNTIF(Contacts!$K$2:$K$501,$B$4&"|"&17)=0,"",INDEX(Contacts!$F$2:$F$501,MATCH($B$4&"|"&17,Contacts!$K$2:$K$501,0))&"") | F35: =IF(COUNTIF(Contacts!$K$2:$K$501,$B$4&"|"&17)=0,"",INDEX(Contacts!$L$2:$L$501,MATCH($B$4&"|"&17,Contacts!$K$2:$K$501,0))&"") | H35: =IF(COUNTIF(Contacts!$K$2:$K$501,$B$4&"|"&17)=0,"",INDEX(Contacts!$E$2:$E$501,MATCH($B$4&"|"&17,Contacts!$K$2:$K$501,0))&"")
A36: =IF(COUNTIF(Contacts!$K$2:$K$501,$B$4&"|"&18)=0,"",INDEX(Contacts!$B$2:$B$501,MATCH($B$4&"|"&18,Contacts!$K$2:$K$501,0))&"") | B36: =IF(COUNTIF(Contacts!$K$2:$K$501,$B$4&"|"&18)=0,"",INDEX(Contacts!$C$2:$C$501,MATCH($B$4&"|"&18,Contacts!$K$2:$K$501,0))&"") | C36: =IF(COUNTIF(Contacts!$K$2:$K$501,$B$4&"|"&18)=0,"",INDEX(Contacts!$D$2:$D$501,MATCH($B$4&"|"&18,Contacts!$K$2:$K$501,0))&"") | D36: =IF($H36="","",IF(ISNUMBER(SEARCH("@",$H36)),HYPERLINK("mailto:"&$H36,$H36),$H36)) | E36: =IF(COUNTIF(Contacts!$K$2:$K$501,$B$4&"|"&18)=0,"",INDEX(Contacts!$F$2:$F$501,MATCH($B$4&"|"&18,Contacts!$K$2:$K$501,0))&"") | F36: =IF(COUNTIF(Contacts!$K$2:$K$501,$B$4&"|"&18)=0,"",INDEX(Contacts!$L$2:$L$501,MATCH($B$4&"|"&18,Contacts!$K$2:$K$501,0))&"") | H36: =IF(COUNTIF(Contacts!$K$2:$K$501,$B$4&"|"&18)=0,"",INDEX(Contacts!$E$2:$E$501,MATCH($B$4&"|"&18,Contacts!$K$2:$K$501,0))&"")
A37: =IF(COUNTIF(Contacts!$K$2:$K$501,$B$4&"|"&19)=0,"",INDEX(Contacts!$B$2:$B$501,MATCH($B$4&"|"&19,Contacts!$K$2:$K$501,0))&"") | B37: =IF(COUNTIF(Contacts!$K$2:$K$501,$B$4&"|"&19)=0,"",INDEX(Contacts!$C$2:$C$501,MATCH($B$4&"|"&19,Contacts!$K$2:$K$501,0))&"") | C37: =IF(COUNTIF(Contacts!$K$2:$K$501,$B$4&"|"&19)=0,"",INDEX(Contacts!$D$2:$D$501,MATCH($B$4&"|"&19,Contacts!$K$2:$K$501,0))&"") | D37: =IF($H37="","",IF(ISNUMBER(SEARCH("@",$H37)),HYPERLINK("mailto:"&$H37,$H37),$H37)) | E37: =IF(COUNTIF(Contacts!$K$2:$K$501,$B$4&"|"&19)=0,"",INDEX(Contacts!$F$2:$F$501,MATCH($B$4&"|"&19,Contacts!$K$2:$K$501,0))&"") | F37: =IF(COUNTIF(Contacts!$K$2:$K$501,$B$4&"|"&19)=0,"",INDEX(Contacts!$L$2:$L$501,MATCH($B$4&"|"&19,Contacts!$K$2:$K$501,0))&"") | H37: =IF(COUNTIF(Contacts!$K$2:$K$501,$B$4&"|"&19)=0,"",INDEX(Contacts!$E$2:$E$501,MATCH($B$4&"|"&19,Contacts!$K$2:$K$501,0))&"")
A38: =IF(COUNTIF(Contacts!$K$2:$K$501,$B$4&"|"&20)=0,"",INDEX(Contacts!$B$2:$B$501,MATCH($B$4&"|"&20,Contacts!$K$2:$K$501,0))&"") | B38: =IF(COUNTIF(Contacts!$K$2:$K$501,$B$4&"|"&20)=0,"",INDEX(Contacts!$C$2:$C$501,MATCH($B$4&"|"&20,Contacts!$K$2:$K$501,0))&"") | C38: =IF(COUNTIF(Contacts!$K$2:$K$501,$B$4&"|"&20)=0,"",INDEX(Contacts!$D$2:$D$501,MATCH($B$4&"|"&20,Contacts!$K$2:$K$501,0))&"") | D38: =IF($H38="","",IF(ISNUMBER(SEARCH("@",$H38)),HYPERLINK("mailto:"&$H38,$H38),$H38)) | E38: =IF(COUNTIF(Contacts!$K$2:$K$501,$B$4&"|"&20)=0,"",INDEX(Contacts!$F$2:$F$501,MATCH($B$4&"|"&20,Contacts!$K$2:$K$501,0))&"") | F38: =IF(COUNTIF(Contacts!$K$2:$K$501,$B$4&"|"&20)=0,"",INDEX(Contacts!$L$2:$L$501,MATCH($B$4&"|"&20,Contacts!$K$2:$K$501,0))&"") | H38: =IF(COUNTIF(Contacts!$K$2:$K$501,$B$4&"|"&20)=0,"",INDEX(Contacts!$E$2:$E$501,MATCH($B$4&"|"&20,Contacts!$K$2:$K$501,0))&"")
A39: =IF($B$4="","",IF(COUNTIF(Contacts!$A$2:$A$501,$B$4)=0,"No contacts entered yet for this builder - add them on the Contacts tab.",IF(COUNTIF(Contacts!$A$2:$A$501,$B$4)>20,"Showing the first 20 of "&COUNTIF(Contacts!$A$2:$A$501,$B$4)&" contacts - see the Contacts tab for the rest.","")))
A41: TITLE COMPANY & ESCROW TEAM
A42: Title Company | B42: =IF($H$2="","-",IF(INDEX(Builders!$B$2:$B$201,$H$2)="","-",INDEX(Builders!$B$2:$B$201,$H$2)))
A43: Role | B43: Name | C43: Phone | D43: Email
...

Sheet Builders
A1: Builder Name | B1: Title Company | C1: Dropbox Folder (paste full link) | D1: Concession Amount / % | E1: Concessions Calculated From | F1: Allowed Uses & Concession Details | G1: Special Process & Incentives | H1: Communication Rules (who to CC, etc.) | I1: General Notes

Sheet Contacts
A1: Builder Name | B1: Role | C1: Contact Name | D1: Phone | E1: Email | F1: What They Handle / When to Contact | G1: Assistant Name | H1: Assistant Phone | I1: Assistant Email | J1: Notes | K1: AUTO - KEY (hidden - do not touch) | L1: AUTO - ASSISTANT (hidden - do not touch)
K2: =IF($A2="","",$A2&"|"&COUNTIF($A$2:$A2,$A2)) | L2: =IF($G2="","",$G2&IF($H2="",""," / "&$H2)&IF($I2="",""," / "&$I2))
K3: =IF($A3="","",$A3&"|"&COUNTIF($A$2:$A3,$A3)) | L3: =IF($G3="","",$G3&IF($H3="",""," / "&$H3)&IF($I3="",""," / "&$I3))
K4: =IF($A4="","",$A4&"|"&COUNTIF($A$2:$A4,$A4)) | L4: =IF($G4="","",$G4&IF($H4="",""," / "&$H4)&IF($I4="",""," / "&$I4))
K5: =IF($A5="","",$A5&"|"&COUNTIF($A$2:$A5,$A5)) | L5: =IF($G5="","",$G5&IF($H5="",""," / "&$H5)&IF($I5="",""," / "&$I5))
K6: =IF($A6="","",$A6&"|"&COUNTIF($A$2:$A6,$A6)) | L6: =IF($G6="","",$G6&IF($H6="",""," / "&$H6)&IF($I6="",""," / "&$I6))
K7: =IF($A7="","",$A7&"|"&COUNTIF($A$2:$A7,$A7)) | L7: =IF($G7="","",$G7&IF($H7="",""," / "&$H7)&IF($I7="",""," / "&$I7))
K8: =IF($A8="","",$A8&"|"&COUNTIF($A$2:$A8,$A8)) | L8: =IF($G8="","",$G8&IF($H8="",""," / "&$H8)&IF($I8="",""," / "&$I8))
K9: =IF($A9="","",$A9&"|"&COUNTIF($A$2:$A9,$A9)) | L9: =IF($G9="","",$G9&IF($H9="",""," / "&$H9)&IF($I9="",""," / "&$I9))
K10: =IF($A10="","",$A10&"|"&COUNTIF($A$2:$A10,$A10)) | L10: =IF($G10="","",$G10&IF($H10="",""," / "&$H10)&IF($I10="",""," / "&$I10))
K11: =IF($A11="","",$A11&"|"&COUNTIF($A$2:$A11,$A11)) | L11: =IF($G11="","",$G11&IF($H11="",""," / "&$H11)&IF($I11="",""," / "&$I11))
K12: =IF($A12="","",$A12&"|"&COUNTIF($A$2:$A12,$A12)) | L12: =IF($G12="","",$G12&IF($H12="",""," / "&$H12)&IF($I12="",""," / "&$I12))
K13: =IF($A13="","",$A13&"|"&COUNTIF($A$2:$A13,$A13)) | L13: =IF($G13="","",$G13&IF($H13="",""," / "&$H13)&IF($I13="",""," / "&$I13))
... K501: =IF($A501="","",$A501&"|"&COUNTIF($A$2:$A501,$A501)) | L501: =IF($G501="","",$G501&IF($H501="",""," / "&$H501)&IF($I501="",""," / "&$I501))

Sheet Title Companies
A1: Title Company | B1: Team / Group Email | C1: Office Phone | D1: Office Address | E1: Notes

Sheet Title Contacts
A1: Title Company | B1: Role | C1: Contact Name | D1: Phone | E1: Email | F1: Notes | G1: AUTO - KEY (hidden - do not touch)
G2: =IF($A2="","",$A2&"|"&COUNTIF($A$2:$A2,$A2))
G3: =IF($A3="","",$A3&"|"&COUNTIF($A$2:$A3,$A3))
G4: =IF($A4="","",$A4&"|"&COUNTIF($A$2:$A4,$A4))
G5: =IF($A5="","",$A5&"|"&COUNTIF($A$2:$A5,$A5))
G6: =IF($A6="","",$A6&"|"&COUNTIF($A$2:$A6,$A6))
G7: =IF($A7="","",$A7&"|"&COUNTIF($A$2:$A7,$A7))
G8: =IF($A8="","",$A8&"|"&COUNTIF($A$2:$A8,$A8))
G9: =IF($A9="","",$A9&"|"&COUNTIF($A$2:$A9,$A9))
G10: =IF($A10="","",$A10&"|"&COUNTIF($A$2:$A10,$A10))
G11: =IF($A11="","",$A11&"|"&COUNTIF($A$2:$A11,$A11))
G12: =IF($A12="","",$A12&"|"&COUNTIF($A$2:$A12,$A12))
G13: =IF($A13="","",$A13&"|"&COUNTIF($A$2:$A13,$A13))
... G601: =IF($A601="","",$A601&"|"&COUNTIF($A$2:$A601,$A601))

Sheet General Contacts
A1: Name | B1: Company or Role | C1: Phone | D1: Second Phone | E1: Email | F1: Second Email | G1: Notes

Sheet To Fill In
A1: WHAT'S STILL MISSING
A2: Updates automatically. MISSING = nothing entered yet for that builder. Nothing to type on this tab - fill gaps in on the green tabs.
A4: Builder | B4: Title Company | C4: Dropbox | D4: Concession Terms | E4: Allowed Uses | F4: Owner | G4: Listing Agent | H4: Builder Rep | I4: Builder Docs POC | J4: Appraisal POC | K4: Escrow Agent | L4: Escrow Assistant | M4: # Missing
A5: =IF(Builders!$A2="","",Builders!$A2) | B5: =IF($A5="","",IF(Builders!$B2="","MISSING","OK")) | C5: =IF($A5="","",IF(Builders!$C2="","MISSING","OK")) | D5: =IF($A5="","",IF(Builders!$D2="","MISSING","OK")) | E5: =IF($A5="","",IF(Builders!$F2="","MISSING","OK")) | F5: =IF($A5="","",IF(COUNTIFS(Contacts!$A$2:$A$501,$A5,Contacts!$B$2:$B$501,"*Owner*")+COUNTIFS(Contacts!$A$2:$A$501,$A5,Contacts!$F$2:$F$501,"*owner*")=0,"MISSING","OK")) | G5: =IF($A5="","",IF(COUNTIFS(Contacts!$A$2:$A$501,$A5,Contacts!$B$2:$B$501,"*Listing*")+COUNTIFS(Contacts!$A$2:$A$501,$A5,Contacts!$F$2:$F$501,"*listing agent*")=0,"MISSING","OK")) | H5: =IF($A5="","",IF(COUNTIFS(Contacts!$A$2:$A$501,$A5,Contacts!$B$2:$B$501,"*Builder Rep*")+COUNTIFS(Contacts!$A$2:$A$501,$A5,Contacts!$B$2:$B$501,"Sales*")=0,"MISSING","OK")) | I5: =IF($A5="","",IF(COUNTIFS(Contacts!$A$2:$A$501,$A5,Contacts!$B$2:$B$501,"*Docs*")+COUNTIFS(Contacts!$A$2:$A$501,$A5,Contacts!$F$2:$F$501,"*builder doc*")=0,"MISSING","OK")) | J5: =IF($A5="","",IF(COUNTIFS(Contacts!$A$2:$A$501,$A5,Contacts!$B$2:$B$501,"*Appraisal*")+COUNTIFS(Contacts!$A$2:$A$501,$A5,Contacts!$F$2:$F$501,"*apprais*")=0,"MISSING","OK")) | K5: =IF($A5="","",IF(Builders!$B2="","MISSING",IF(COUNTIFS('Title Contacts'!$A$2:$A$601,Builders!$B2,'Title Contacts'!$B$2:$B$601,"*agent*",'Title Contacts'!$C$2:$C$601,"<>")>0,"OK","MISSING"))) | L5: =IF($A5="","",IF(Builders!$B2="","MISSING",IF(COUNTIFS('Title Contacts'!$A$2:$A$601,Builders!$B2,'Title Contacts'!$B$2:$B$601,"*assistant*",'Title Contacts'!$C$2:$C$601,"<>")>0,"OK","MISSING"))) | M5: =IF($A5="","",COUNTIF(B5:L5,"MISSING"))
A6: =IF(Builders!$A3="","",Builders!$A3) | B6: =IF($A6="","",IF(Builders!$B3="","MISSING","OK")) | C6: =IF($A6="","",IF(Builders!$C3="","MISSING","OK")) | D6: =IF($A6="","",IF(Builders!$D3="","MISSING","OK")) | E6: =IF($A6="","",IF(Builders!$F3="","MISSING","OK")) | F6: =IF($A6="","",IF(COUNTIFS(Contacts!$A$2:$A$501,$A6,Contacts!$B$2:$B$501,"*Owner*")+COUNTIFS(Contacts!$A$2:$A$501,$A6,Contacts!$F$2:$F$501,"*owner*")=0,"MISSING","OK")) | G6: =IF($A6="","",IF(COUNTIFS(Contacts!$A$2:$A$501,$A6,Contacts!$B$2:$B$501,"*Listing*")+COUNTIFS(Contacts!$A$2:$A$501,$A6,Contacts!$F$2:$F$501,"*listing agent*")=0,"MISSING","OK")) | H6: =IF($A6="","",IF(COUNTIFS(Contacts!$A$2:$A$501,$A6,Contacts!$B$2:$B$501,"*Builder Rep*")+COUNTIFS(Contacts!$A$2:$A$501,$A6,Contacts!$B$2:$B$501,"Sales*")=0,"MISSING","OK")) | I6: =IF($A6="","",IF(COUNTIFS(Contacts!$A$2:$A$501,$A6,Contacts!$B$2:$B$501,"*Docs*")+COUNTIFS(Contacts!$A$2:$A$501,$A6,Contacts!$F$2:$F$501,"*builder doc*")=0,"MISSING","OK")) | J6: =IF($A6="","",IF(COUNTIFS(Contacts!$A$2:$A$501,$A6,Contacts!$B$2:$B$501,"*Appraisal*")+COUNTIFS(Contacts!$A$2:$A$501,$A6,Contacts!$F$2:$F$501,"*apprais*")=0,"MISSING","OK")) | K6: =IF($A6="","",IF(Builders!$B3="","MISSING",IF(COUNTIFS('Title Contacts'!$A$2:$A$601,Builders!$B3,'Title Contacts'!$B$2:$B$601,"*agent*",'Title Contacts'!$C$2:$C$601,"<>")>0,"OK","MISSING"))) | L6: =IF($A6="","",IF(Builders!$B3="","MISSING",IF(COUNTIFS('Title Contacts'!$A$2:$A$601,Builders!$B3,'Title Contacts'!$B$2:$B$601,"*assistant*",'Title Contacts'!$C$2:$C$601,"<>")>0,"OK","MISSING"))) | M6: =IF($A6="","",COUNTIF(B6:L6,"MISSING"))
A7: =IF(Builders!$A4="","",Builders!$A4) | B7: =IF($A7="","",IF(Builders!$B4="","MISSING","OK")) | C7: =IF($A7="","",IF(Builders!$C4="","MISSING","OK")) | D7: =IF($A7="","",IF(Builders!$D4="","MISSING","OK")) | E7: =IF($A7="","",IF(Builders!$F4="","MISSING","OK")) | F7: =IF($A7="","",IF(COUNTIFS(Contacts!$A$2:$A$501,$A7,Contacts!$B$2:$B$501,"*Owner*")+COUNTIFS(Contacts!$A$2:$A$501,$A7,Contacts!$F$2:$F$501,"*owner*")=0,"MISSING","OK")) | G7: =IF($A7="","",IF(COUNTIFS(Contacts!$A$2:$A$501,$A7,Contacts!$B$2:$B$501,"*Listing*")+COUNTIFS(Contacts!$A$2:$A$501,$A7,Contacts!$F$2:$F$501,"*listing agent*")=0,"MISSING","OK")) | H7: =IF($A7="","",IF(COUNTIFS(Contacts!$A$2:$A$501,$A7,Contacts!$B$2:$B$501,"*Builder Rep*")+COUNTIFS(Contacts!$A$2:$A$501,$A7,Contacts!$B$2:$B$501,"Sales*")=0,"MISSING","OK")) | I7: =IF($A7="","",IF(COUNTIFS(Contacts!$A$2:$A$501,$A7,Contacts!$B$2:$B$501,"*Docs*")+COUNTIFS(Contacts!$A$2:$A$501,$A7,Contacts!$F$2:$F$501,"*builder doc*")=0,"MISSING","OK")) | J7: =IF($A7="","",IF(COUNTIFS(Contacts!$A$2:$A$501,$A7,Contacts!$B$2:$B$501,"*Appraisal*")+COUNTIFS(Contacts!$A$2:$A$501,$A7,Contacts!$F$2:$F$501,"*apprais*")=0,"MISSING","OK")) | K7: =IF($A7="","",IF(Builders!$B4="","MISSING",IF(COUNTIFS('Title Contacts'!$A$2:$A$601,Builders!$B4,'Title Contacts'!$B$2:$B$601,"*agent*",'Title Contacts'!$C$2:$C$601,"<>")>0,"OK","MISSING"))) | L7: =IF($A7="","",IF(Builders!$B4="","MISSING",IF(COUNTIFS('Title Contacts'!$A$2:$A$601,Builders!$B4,'Title Contacts'!$B$2:$B$601,"*assistant*",'Title Contacts'!$C$2:$C$601,"<>")>0,"OK","MISSING"))) | M7: =IF($A7="","",COUNTIF(B7:L7,"MISSING"))
A8: =IF(Builders!$A5="","",Builders!$A5) | B8: =IF($A8="","",IF(Builders!$B5="","MISSING","OK")) | C8: =IF($A8="","",IF(Builders!$C5="","MISSING","OK")) | D8: =IF($A8="","",IF(Builders!$D5="","MISSING","OK")) | E8: =IF($A8="","",IF(Builders!$F5="","MISSING","OK")) | F8: =IF($A8="","",IF(COUNTIFS(Contacts!$A$2:$A$501,$A8,Contacts!$B$2:$B$501,"*Owner*")+COUNTIFS(Contacts!$A$2:$A$501,$A8,Contacts!$F$2:$F$501,"*owner*")=0,"MISSING","OK")) | G8: =IF($A8="","",IF(COUNTIFS(Contacts!$A$2:$A$501,$A8,Contacts!$B$2:$B$501,"*Listing*")+COUNTIFS(Contacts!$A$2:$A$501,$A8,Contacts!$F$2:$F$501,"*listing agent*")=0,"MISSING","OK")) | H8: =IF($A8="","",IF(COUNTIFS(Contacts!$A$2:$A$501,$A8,Contacts!$B$2:$B$501,"*Builder Rep*")+COUNTIFS(Contacts!$A$2:$A$501,$A8,Contacts!$B$2:$B$501,"Sales*")=0,"MISSING","OK")) | I8: =IF($A8="","",IF(COUNTIFS(Contacts!$A$2:$A$501,$A8,Contacts!$B$2:$B$501,"*Docs*")+COUNTIFS(Contacts!$A$2:$A$501,$A8,Contacts!$F$2:$F$501,"*builder doc*")=0,"MISSING","OK")) | J8: =IF($A8="","",IF(COUNTIFS(Contacts!$A$2:$A$501,$A8,Contacts!$B$2:$B$501,"*Appraisal*")+COUNTIFS(Contacts!$A$2:$A$501,$A8,Contacts!$F$2:$F$501,"*apprais*")=0,"MISSING","OK")) | K8: =IF($A8="","",IF(Builders!$B5="","MISSING",IF(COUNTIFS('Title Contacts'!$A$2:$A$601,Builders!$B5,'Title Contacts'!$B$2:$B$601,"*agent*",'Title Contacts'!$C$2:$C$601,"<>")>0,"OK","MISSING"))) | L8: =IF($A8="","",IF(Builders!$B5="","MISSING",IF(COUNTIFS('Title Contacts'!$A$2:$A$601,Builders!$B5,'Title Contacts'!$B$2:$B$601,"*assistant*",'Title Contacts'!$C$2:$C$601,"<>")>0,"OK","MISSING"))) | M8: =IF($A8="","",COUNTIF(B8:L8,"MISSING"))
A9: =IF(Builders!$A6="","",Builders!$A6) | B9: =IF($A9="","",IF(Builders!$B6="","MISSING","OK")) | C9: =IF($A9="","",IF(Builders!$C6="","MISSING","OK")) | D9: =IF($A9="","",IF(Builders!$D6="","MISSING","OK")) | E9: =IF($A9="","",IF(Builders!$F6="","MISSING","OK")) | F9: =IF($A9="","",IF(COUNTIFS(Contacts!$A$2:$A$501,$A9,Contacts!$B$2:$B$501,"*Owner*")+COUNTIFS(Contacts!$A$2:$A$501,$A9,Contacts!$F$2:$F$501,"*owner*")=0,"MISSING","OK")) | G9: =IF($A9="","",IF(COUNTIFS(Contacts!$A$2:$A$501,$A9,Contacts!$B$2:$B$501,"*Listing*")+COUNTIFS(Contacts!$A$2:$A$501,$A9,Contacts!$F$2:$F$501,"*listing agent*")=0,"MISSING","OK")) | H9: =IF($A9="","",IF(COUNTIFS(Contacts!$A$2:$A$501,$A9,Contacts!$B$2:$B$501,"*Builder Rep*")+COUNTIFS(Contacts!$A$2:$A$501,$A9,Contacts!$B$2:$B$501,"Sales*")=0,"MISSING","OK")) | I9: =IF($A9="","",IF(COUNTIFS(Contacts!$A$2:$A$501,$A9,Contacts!$B$2:$B$501,"*Docs*")+COUNTIFS(Contacts!$A$2:$A$501,$A9,Contacts!$F$2:$F$501,"*builder doc*")=0,"MISSING","OK")) | J9: =IF($A9="","",IF(COUNTIFS(Contacts!$A$2:$A$501,$A9,Contacts!$B$2:$B$501,"*Appraisal*")+COUNTIFS(Contacts!$A$2:$A$501,$A9,Contacts!$F$2:$F$501,"*apprais*")=0,"MISSING","OK")) | K9: =IF($A9="","",IF(Builders!$B6="","MISSING",IF(COUNTIFS('Title Contacts'!$A$2:$A$601,Builders!$B6,'Title Contacts'!$B$2:$B$601,"*agent*",'Title Contacts'!$C$2:$C$601,"<>")>0,"OK","MISSING"))) | L9: =IF($A9="","",IF(Builders!$B6="","MISSING",IF(COUNTIFS('Title Contacts'!$A$2:$A$601,Builders!$B6,'Title Contacts'!$B$2:$B$601,"*assistant*",'Title Contacts'!$C$2:$C$601,"<>")>0,"OK","MISSING"))) | M9: =IF($A9="","",COUNTIF(B9:L9,"MISSING"))
A10: =IF(Builders!$A7="","",Builders!$A7) | B10: =IF($A10="","",IF(Builders!$B7="","MISSING","OK")) | C10: =IF($A10="","",IF(Builders!$C7="","MISSING","OK")) | D10: =IF($A10="","",IF(Builders!$D7="","MISSING","OK")) | E10: =IF($A10="","",IF(Builders!$F7="","MISSING","OK")) | F10: =IF($A10="","",IF(COUNTIFS(Contacts!$A$2:$A$501,$A10,Contacts!$B$2:$B$501,"*Owner*")+COUNTIFS(Contacts!$A$2:$A$501,$A10,Contacts!$F$2:$F$501,"*owner*")=0,"MISSING","OK")) | G10: =IF($A10="","",IF(COUNTIFS(Contacts!$A$2:$A$501,$A10,Contacts!$B$2:$B$501,"*Listing*")+COUNTIFS(Contacts!$A$2:$A$501,$A10,Contacts!$F$2:$F$501,"*listing agent*")=0,"MISSING","OK")) | H10: =IF($A10="","",IF(COUNTIFS(Contacts!$A$2:$A$501,$A10,Contacts!$B$2:$B$501,"*Builder Rep*")+COUNTIFS(Contacts!$A$2:$A$501,$A10,Contacts!$B$2:$B$501,"Sales*")=0,"MISSING","OK")) | I10: =IF($A10="","",IF(COUNTIFS(Contacts!$A$2:$A$501,$A10,Contacts!$B$2:$B$501,"*Docs*")+COUNTIFS(Contacts!$A$2:$A$501,$A10,Contacts!$F$2:$F$501,"*builder doc*")=0,"MISSING","OK")) | J10: =IF($A10="","",IF(COUNTIFS(Contacts!$A$2:$A$501,$A10,Contacts!$B$2:$B$501,"*Appraisal*")+COUNTIFS(Contacts!$A$2:$A$501,$A10,Contacts!$F$2:$F$501,"*apprais*")=0,"MISSING","OK")) | K10: =IF($A10="","",IF(Builders!$B7="","MISSING",IF(COUNTIFS('Title Contacts'!$A$2:$A$601,Builders!$B7,'Title Contacts'!$B$2:$B$601,"*agent*",'Title Contacts'!$C$2:$C$601,"<>")>0,"OK","MISSING"))) | L10: =IF($A10="","",IF(Builders!$B7="","MISSING",IF(COUNTIFS('Title Contacts'!$A$2:$A$601,Builders!$B7,'Title Contacts'!$B$2:$B$601,"*assistant*",'Title Contacts'!$C$2:$C$601,"<>")>0,"OK","MISSING"))) | M10: =IF($A10="","",COUNTIF(B10:L10,"MISSING"))
A11: =IF(Builders!$A8="","",Builders!$A8) | B11: =IF($A11="","",IF(Builders!$B8="","MISSING","OK")) | C11: =IF($A11="","",IF(Builders!$C8="","MISSING","OK")) | D11: =IF($A11="","",IF(Builders!$D8="","MISSING","OK")) | E11: =IF($A11="","",IF(Builders!$F8="","MISSING","OK")) | F11: =IF($A11="","",IF(COUNTIFS(Contacts!$A$2:$A$501,$A11,Contacts!$B$2:$B$501,"*Owner*")+COUNTIFS(Contacts!$A$2:$A$501,$A11,Contacts!$F$2:$F$501,"*owner*")=0,"MISSING","OK")) | G11: =IF($A11="","",IF(COUNTIFS(Contacts!$A$2:$A$501,$A11,Contacts!$B$2:$B$501,"*Listing*")+COUNTIFS(Contacts!$A$2:$A$501,$A11,Contacts!$F$2:$F$501,"*listing agent*")=0,"MISSING","OK")) | H11: =IF($A11="","",IF(COUNTIFS(Contacts!$A$2:$A$501,$A11,Contacts!$B$2:$B$501,"*Builder Rep*")+COUNTIFS(Contacts!$A$2:$A$501,$A11,Contacts!$B$2:$B$501,"Sales*")=0,"MISSING","OK")) | I11: =IF($A11="","",IF(COUNTIFS(Contacts!$A$2:$A$501,$A11,Contacts!$B$2:$B$501,"*Docs*")+COUNTIFS(Contacts!$A$2:$A$501,$A11,Contacts!$F$2:$F$501,"*builder doc*")=0,"MISSING","OK")) | J11: =IF($A11="","",IF(COUNTIFS(Contacts!$A$2:$A$501,$A11,Contacts!$B$2:$B$501,"*Appraisal*")+COUNTIFS(Contacts!$A$2:$A$501,$A11,Contacts!$F$2:$F$501,"*apprais*")=0,"MISSING","OK")) | K11: =IF($A11="","",IF(Builders!$B8="","MISSING",IF(COUNTIFS('Title Contacts'!$A$2:$A$601,Builders!$B8,'Title Contacts'!$B$2:$B$601,"*agent*",'Title Contacts'!$C$2:$C$601,"<>")>0,"OK","MISSING"))) | L11: =IF($A11="","",IF(Builders!$B8="","MISSING",IF(COUNTIFS('Title Contacts'!$A$2:$A$601,Builders!$B8,'Title Contacts'!$B$2:$B$601,"*assistant*",'Title Contacts'!$C$2:$C$601,"<>")>0,"OK","MISSING"))) | M11: =IF($A11="","",COUNTIF(B11:L11,"MISSING"))
A12: =IF(Builders!$A9="","",Builders!$A9) | B12: =IF($A12="","",IF(Builders!$B9="","MISSING","OK")) | C12: =IF($A12="","",IF(Builders!$C9="","MISSING","OK")) | D12: =IF($A12="","",IF(Builders!$D9="","MISSING","OK")) | E12: =IF($A12="","",IF(Builders!$F9="","MISSING","OK")) | F12: =IF($A12="","",IF(COUNTIFS(Contacts!$A$2:$A$501,$A12,Contacts!$B$2:$B$501,"*Owner*")+COUNTIFS(Contacts!$A$2:$A$501,$A12,Contacts!$F$2:$F$501,"*owner*")=0,"MISSING","OK")) | G12: =IF($A12="","",IF(COUNTIFS(Contacts!$A$2:$A$501,$A12,Contacts!$B$2:$B$501,"*Listing*")+COUNTIFS(Contacts!$A$2:$A$501,$A12,Contacts!$F$2:$F$501,"*listing agent*")=0,"MISSING","OK")) | H12: =IF($A12="","",IF(COUNTIFS(Contacts!$A$2:$A$501,$A12,Contacts!$B$2:$B$501,"*Builder Rep*")+COUNTIFS(Contacts!$A$2:$A$501,$A12,Contacts!$B$2:$B$501,"Sales*")=0,"MISSING","OK")) | I12: =IF($A12="","",IF(COUNTIFS(Contacts!$A$2:$A$501,$A12,Contacts!$B$2:$B$501,"*Docs*")+COUNTIFS(Contacts!$A$2:$A$501,$A12,Contacts!$F$2:$F$501,"*builder doc*")=0,"MISSING","OK")) | J12: =IF($A12="","",IF(COUNTIFS(Contacts!$A$2:$A$501,$A12,Contacts!$B$2:$B$501,"*Appraisal*")+COUNTIFS(Contacts!$A$2:$A$501,$A12,Contacts!$F$2:$F$501,"*apprais*")=0,"MISSING","OK")) | K12: =IF($A12="","",IF(Builders!$B9="","MISSING",IF(COUNTIFS('Title Contacts'!$A$2:$A$601,Builders!$B9,'Title Contacts'!$B$2:$B$601,"*agent*",'Title Contacts'!$C$2:$C$601,"<>")>0,"OK","MISSING"))) | L12: =IF($A12="","",IF(Builders!$B9="","MISSING",IF(COUNTIFS('Title Contacts'!$A$2:$A$601,Builders!$B9,'Title Contacts'!$B$2:$B$601,"*assistant*",'Title Contacts'!$C$2:$C$601,"<>")>0,"OK","MISSING"))) | M12: =IF($A12="","",COUNTIF(B12:L12,"MISSING"))
A13: =IF(Builders!$A10="","",Builders!$A10) | B13: =IF($A13="","",IF(Builders!$B10="","MISSING","OK")) | C13: =IF($A13="","",IF(Builders!$C10="","MISSING","OK")) | D13: =IF($A13="","",IF(Builders!$D10="","MISSING","OK")) | E13: =IF($A13="","",IF(Builders!$F10="","MISSING","OK")) | F13: =IF($A13="","",IF(COUNTIFS(Contacts!$A$2:$A$501,$A13,Contacts!$B$2:$B$501,"*Owner*")+COUNTIFS(Contacts!$A$2:$A$501,$A13,Contacts!$F$2:$F$501,"*owner*")=0,"MISSING","OK")) | G13: =IF($A13="","",IF(COUNTIFS(Contacts!$A$2:$A$501,$A13,Contacts!$B$2:$B$501,"*Listing*")+COUNTIFS(Contacts!$A$2:$A$501,$A13,Contacts!$F$2:$F$501,"*listing agent*")=0,"MISSING","OK")) | H13: =IF($A13="","",IF(COUNTIFS(Contacts!$A$2:$A$501,$A13,Contacts!$B$2:$B$501,"*Builder Rep*")+COUNTIFS(Contacts!$A$2:$A$501,$A13,Contacts!$B$2:$B$501,"Sales*")=0,"MISSING","OK")) | I13: =IF($A13="","",IF(COUNTIFS(Contacts!$A$2:$A$501,$A13,Contacts!$B$2:$B$501,"*Docs*")+COUNTIFS(Contacts!$A$2:$A$501,$A13,Contacts!$F$2:$F$501,"*builder doc*")=0,"MISSING","OK")) | J13: =IF($A13="","",IF(COUNTIFS(Contacts!$A$2:$A$501,$A13,Contacts!$B$2:$B$501,"*Appraisal*")+COUNTIFS(Contacts!$A$2:$A$501,$A13,Contacts!$F$2:$F$501,"*apprais*")=0,"MISSING","OK")) | K13: =IF($A13="","",IF(Builders!$B10="","MISSING",IF(COUNTIFS('Title Contacts'!$A$2:$A$601,Builders!$B10,'Title Contacts'!$B$2:$B$601,"*agent*",'Title Contacts'!$C$2:$C$601,"<>")>0,"OK","MISSING"))) | L13: =IF($A13="","",IF(Builders!$B10="","MISSING",IF(COUNTIFS('Title Contacts'!$A$2:$A$601,Builders!$B10,'Title Contacts'!$B$2:$B$601,"*assistant*",'Title Contacts'!$C$2:$C$601,"<>")>0,"OK","MISSING"))) | M13: =IF($A13="","",COUNTIF(B13:L13,"MISSING"))
A14: =IF(Builders!$A11="","",Builders!$A11) | B14: =IF($A14="","",IF(Builders!$B11="","MISSING","OK")) | C14: =IF($A14="","",IF(Builders!$C11="","MISSING","OK")) | D14: =IF($A14="","",IF(Builders!$D11="","MISSING","OK")) | E14: =IF($A14="","",IF(Builders!$F11="","MISSING","OK")) | F14: =IF($A14="","",IF(COUNTIFS(Contacts!$A$2:$A$501,$A14,Contacts!$B$2:$B$501,"*Owner*")+COUNTIFS(Contacts!$A$2:$A$501,$A14,Contacts!$F$2:$F$501,"*owner*")=0,"MISSING","OK")) | G14: =IF($A14="","",IF(COUNTIFS(Contacts!$A$2:$A$501,$A14,Contacts!$B$2:$B$501,"*Listing*")+COUNTIFS(Contacts!$A$2:$A$501,$A14,Contacts!$F$2:$F$501,"*listing agent*")=0,"MISSING","OK")) | H14: =IF($A14="","",IF(COUNTIFS(Contacts!$A$2:$A$501,$A14,Contacts!$B$2:$B$501,"*Builder Rep*")+COUNTIFS(Contacts!$A$2:$A$501,$A14,Contacts!$B$2:$B$501,"Sales*")=0,"MISSING","OK")) | I14: =IF($A14="","",IF(COUNTIFS(Contacts!$A$2:$A$501,$A14,Contacts!$B$2:$B$501,"*Docs*")+COUNTIFS(Contacts!$A$2:$A$501,$A14,Contacts!$F$2:$F$501,"*builder doc*")=0,"MISSING","OK")) | J14: =IF($A14="","",IF(COUNTIFS(Contacts!$A$2:$A$501,$A14,Contacts!$B$2:$B$501,"*Appraisal*")+COUNTIFS(Contacts!$A$2:$A$501,$A14,Contacts!$F$2:$F$501,"*apprais*")=0,"MISSING","OK")) | K14: =IF($A14="","",IF(Builders!$B11="","MISSING",IF(COUNTIFS('Title Contacts'!$A$2:$A$601,Builders!$B11,'Title Contacts'!$B$2:$B$601,"*agent*",'Title Contacts'!$C$2:$C$601,"<>")>0,"OK","MISSING"))) | L14: =IF($A14="","",IF(Builders!$B11="","MISSING",IF(COUNTIFS('Title Contacts'!$A$2:$A$601,Builders!$B11,'Title Contacts'!$B$2:$B$601,"*assistant*",'Title Contacts'!$C$2:$C$601,"<>")>0,"OK","MISSING"))) | M14: =IF($A14="","",COUNTIF(B14:L14,"MISSING"))
A15: =IF(Builders!$A12="","",Builders!$A12) | B15: =IF($A15="","",IF(Builders!$B12="","MISSING","OK")) | C15: =IF($A15="","",IF(Builders!$C12="","MISSING","OK")) | D15: =IF($A15="","",IF(Builders!$D12="","MISSING","OK")) | E15: =IF($A15="","",IF(Builders!$F12="","MISSING","OK")) | F15: =IF($A15="","",IF(COUNTIFS(Contacts!$A$2:$A$501,$A15,Contacts!$B$2:$B$501,"*Owner*")+COUNTIFS(Contacts!$A$2:$A$501,$A15,Contacts!$F$2:$F$501,"*owner*")=0,"MISSING","OK")) | G15: =IF($A15="","",IF(COUNTIFS(Contacts!$A$2:$A$501,$A15,Contacts!$B$2:$B$501,"*Listing*")+COUNTIFS(Contacts!$A$2:$A$501,$A15,Contacts!$F$2:$F$501,"*listing agent*")=0,"MISSING","OK")) | H15: =IF($A15="","",IF(COUNTIFS(Contacts!$A$2:$A$501,$A15,Contacts!$B$2:$B$501,"*Builder Rep*")+COUNTIFS(Contacts!$A$2:$A$501,$A15,Contacts!$B$2:$B$501,"Sales*")=0,"MISSING","OK")) | I15: =IF($A15="","",IF(COUNTIFS(Contacts!$A$2:$A$501,$A15,Contacts!$B$2:$B$501,"*Docs*")+COUNTIFS(Contacts!$A$2:$A$501,$A15,Contacts!$F$2:$F$501,"*builder doc*")=0,"MISSING","OK")) | J15: =IF($A15="","",IF(COUNTIFS(Contacts!$A$2:$A$501,$A15,Contacts!$B$2:$B$501,"*Appraisal*")+COUNTIFS(Contacts!$A$2:$A$501,$A15,Contacts!$F$2:$F$501,"*apprais*")=0,"MISSING","OK")) | K15: =IF($A15="","",IF(Builders!$B12="","MISSING",IF(COUNTIFS('Title Contacts'!$A$2:$A$601,Builders!$B12,'Title Contacts'!$B$2:$B$601,"*agent*",'Title Contacts'!$C$2:$C$601,"<>")>0,"OK","MISSING"))) | L15: =IF($A15="","",IF(Builders!$B12="","MISSING",IF(COUNTIFS('Title Contacts'!$A$2:$A$601,Builders!$B12,'Title Contacts'!$B$2:$B$601,"*assistant*",'Title Contacts'!$C$2:$C$601,"<>")>0,"OK","MISSING"))) | M15: =IF($A15="","",COUNTIF(B15:L15,"MISSING"))
A16: =IF(Builders!$A13="","",Builders!$A13) | B16: =IF($A16="","",IF(Builders!$B13="","MISSING","OK")) | C16: =IF($A16="","",IF(Builders!$C13="","MISSING","OK")) | D16: =IF($A16="","",IF(Builders!$D13="","MISSING","OK")) | E16: =IF($A16="","",IF(Builders!$F13="","MISSING","OK")) | F16: =IF($A16="","",IF(COUNTIFS(Contacts!$A$2:$A$501,$A16,Contacts!$B$2:$B$501,"*Owner*")+COUNTIFS(Contacts!$A$2:$A$501,$A16,Contacts!$F$2:$F$501,"*owner*")=0,"MISSING","OK")) | G16: =IF($A16="","",IF(COUNTIFS(Contacts!$A$2:$A$501,$A16,Contacts!$B$2:$B$501,"*Listing*")+COUNTIFS(Contacts!$A$2:$A$501,$A16,Contacts!$F$2:$F$501,"*listing agent*")=0,"MISSING","OK")) | H16: =IF($A16="","",IF(COUNTIFS(Contacts!$A$2:$A$501,$A16,Contacts!$B$2:$B$501,"*Builder Rep*")+COUNTIFS(Contacts!$A$2:$A$501,$A16,Contacts!$B$2:$B$501,"Sales*")=0,"MISSING","OK")) | I16: =IF($A16="","",IF(COUNTIFS(Contacts!$A$2:$A$501,$A16,Contacts!$B$2:$B$501,"*Docs*")+COUNTIFS(Contacts!$A$2:$A$501,$A16,Contacts!$F$2:$F$501,"*builder doc*")=0,"MISSING","OK")) | J16: =IF($A16="","",IF(COUNTIFS(Contacts!$A$2:$A$501,$A16,Contacts!$B$2:$B$501,"*Appraisal*")+COUNTIFS(Contacts!$A$2:$A$501,$A16,Contacts!$F$2:$F$501,"*apprais*")=0,"MISSING","OK")) | K16: =IF($A16="","",IF(Builders!$B13="","MISSING",IF(COUNTIFS('Title Contacts'!$A$2:$A$601,Builders!$B13,'Title Contacts'!$B$2:$B$601,"*agent*",'Title Contacts'!$C$2:$C$601,"<>")>0,"OK","MISSING"))) | L16: =IF($A16="","",IF(Builders!$B13="","MISSING",IF(COUNTIFS('Title Contacts'!$A$2:$A$601,Builders!$B13,'Title Contacts'!$B$2:$B$601,"*assistant*",'Title Contacts'!$C$2:$C$601,"<>")>0,"OK","MISSING"))) | M16: =IF($A16="","",COUNTIF(B16:L16,"MISSING"))
... A204: =IF(Builders!$A201="","",Builders!$A201) | B204: =IF($A204="","",IF(Builders!$B201="","MISSING","OK")) | C204: =IF($A204="","",IF(Builders!$C201="","MISSING","OK")) | D204: =IF($A204="","",IF(Builders!$D201="","MISSING","OK")) | E204: =IF($A204="","",IF(Builders!$F201="","MISSING","OK")) | F204: =IF($A204="","",IF(COUNTIFS(Contacts!$A$2:$A$501,$A204,Contacts!$B$2:$B$501,"*Owner*")+COUNTIFS(Contacts!$A$2:$A$501,$A204,Contacts!$F$2:$F$501,"*owner*")=0,"MISSING","OK")) | G204: =IF($A204="","",IF(COUNTIFS(Contacts!$A$2:$A$501,$A204,Contacts!$B$2:$B$501,"*Listing*")+COUNTIFS(Contacts!$A$2:$A$501,$A204,Contacts!$F$2:$F$501,"*listing agent*")=0,"MISSING","OK")) | H204: =IF($A204="","",IF(COUNTIFS(Contacts!$A$2:$A$501,$A204,Contacts!$B$2:$B$501,"*Builder Rep*")+COUNTIFS(Contacts!$A$2:$A$501,$A204,Contacts!$B$2:$B$501,"Sales*")=0,"MISSING","OK")) | I204: =IF($A204="","",IF(COUNTIFS(Contacts!$A$2:$A$501,$A204,Contacts!$B$2:$B$501,"*Docs*")+COUNTIFS(Contacts!$A$2:$A$501,$A204,Contacts!$F$2:$F$501,"*builder doc*")=0,"MISSING","OK")) | J204: =IF($A204="","",IF(COUNTIFS(Contacts!$A$2:$A$501,$A204,Contacts!$B$2:$B$501,"*Appraisal*")+COUNTIFS(Contacts!$A$2:$A$501,$A204,Contacts!$F$2:$F$501,"*apprais*")=0,"MISSING","OK")) | K204: =IF($A204="","",IF(Builders!$B201="","MISSING",IF(COUNTIFS('Title Contacts'!$A$2:$A$601,Builders!$B201,'Title Contacts'!$B$2:$B$601,"*agent*",'Title Contacts'!$C$2:$C$601,"<>")>0,"OK","MISSING"))) | L204: =IF($A204="","",IF(Builders!$B201="","MISSING",IF(COUNTIFS('Title Contacts'!$A$2:$A$601,Builders!$B201,'Title Contacts'!$B$2:$B$601,"*assistant*",'Title Contacts'!$C$2:$C$601,"<>")>0,"OK","MISSING"))) | M204: =IF($A204="","",COUNTIF(B204:L204,"MISSING"))

Sheet Lists
A1: Role | B1: Title Role | C1: Column A feeds the Role dropdown on Contacts, column B the one on Title Contacts. Add a value here to make it selectable (see Start Here > Maintenance to extend past row 31).
B2: Escrow Agent
B3: Escrow Assistant
B4: Closer
B5: Title Officer
B6: Processor
B7: Post Closer
